Workbook

Sheet Sheet1
A1: SR no | B1: Notification No | C1: Receipt Date | D1: S R NO | E1: FAULT REPORTED | F1: TAG | G1: ESN NO | H1: Status | I1: MATERIAL CODE | J1: PRESCAN Code | K1: PRESCAN Name | L1: Object Part | M1: Object Part DESCRIPTION | N1: DAMAGE | O1: DAMAGE DESCRIPTION | P1: CAUSE CODE | Q1: CAUSE DESCRIPTION | R1: ACTION CODE | S1: ACTION/REPAIR TASK | T1: REPAIR TASK DESCRIPTION | U1: EXTRA REMARK FOR IR | V1: REASON CODE | W1: REASON IR | X1: REPAIRED TECH code | Y1: REPAIRED TECH NAME | Z1: PART LOCATION | AA1: DECLERED DATE | AB1: Remarks | AC1: k | AD1: panding | CN1: Status | CO1: Tag Details | CP1: MATERIAL CODE
A2: 1 | B2: 1009431894 | C2: 05.07.2021 | D2: W3.031 | E2: STANDBY | F2: Def Tag Available | G2: 853151711514 | H2: IR | I2: TECH HD | J2: A041 | K2: =VLOOKUP(J2,Sheet2!A:B,2,0) -> PRASHANT,AKASH | L2: 1 | M2: =VLOOKUP(L2,Sheet2!D:E,2,0) -> Power Supply Section | N2: 1 | O2: =VLOOKUP(N2,Sheet2!G:H,2,0) -> Dead | P2: 11 | Q2: =VLOOKUP(P2,Sheet2!J:K,2,0) -> IR Declared due to CID -TA | R2: IR | S2: =VLOOKUP(R2,Sheet2!N:O,2,0) -> IREPARABLE | T2: =VLOOKUP(P2,Sheet2!Q:R,2,0) -> IR Normal - Track burn out | U2: IR CID - Tampered Track burn out | V2: 4 | W2: =VLOOKUP(V2,Sheet2!Q:R,2,0) -> IR CID - Tampered Track burn out | X2: =J2 -> A041 | Y2: =VLOOKUP(X2,Sheet2!A:B,2,0) -> PRASHANT,AKASH | Z2: UD1,U8 | AA2: 02.09.2021 | AB2: - | AC2: =LEFT(G2,2) -> 85 | AE2: HIMANSHU | CN2: BER REPAIRED | CO2: STD | CP2: STD
A3: 1 | B3: 1009616011 | C3: 28.05.2021 | D3: N A | E3: DEAD | F3: Def Tag Available | G3: 853343732246 | H3: IR | I3: TECH HD | J3: A041 | K3: =VLOOKUP(J3,Sheet2!A:B,2,0) -> PRASHANT,AKASH | L3: 1 | M3: =VLOOKUP(L3,Sheet2!D:E,2,0) -> Power Supply Section | N3: 1 | O3: =VLOOKUP(N3,Sheet2!G:H,2,0) -> Dead | P3: 11 | Q3: =VLOOKUP(P3,Sheet2!J:K,2,0) -> IR Declared due to CID -TA | R3: IR | S3: =VLOOKUP(R3,Sheet2!N:O,2,0) -> IREPARABLE | T3: =VLOOKUP(P3,Sheet2!Q:R,2,0) -> IR Normal - Track burn out | U3: IR CID - Tampered Track burn out | V3: 4 | W3: =VLOOKUP(V3,Sheet2!Q:R,2,0) -> IR CID - Tampered Track burn out | X3: =J3 -> A041 | Y3: =VLOOKUP(X3,Sheet2!A:B,2,0) -> PRASHANT,AKASH | Z3: UD1,U8,U10,R323,R7,R7 | AA3: 02.09.2021 | AB3: - | AC3: =LEFT(G3,2) -> 85 | AE3: HIMANSHU | CN3: REPAIRED | CO3: KAON HD | CP3: KAON HD
A4: 2 | B4: 1009616003 | C4: 20.01.2021 | D4: W4.320 | E4: DEAD | F4: Def Tag Available | G4: 853128718055 | H4: IR | I4: TECH HD | J4: A041 | K4: =VLOOKUP(J4,Sheet2!A:B,2,0) -> PRASHANT,AKASH | L4: 1 | M4: =VLOOKUP(L4,Sheet2!D:E,2,0) -> Power Supply Section | N4: 1 | O4: =VLOOKUP(N4,Sheet2!G:H,2,0) -> Dead | P4: 11 | Q4: =VLOOKUP(P4,Sheet2!J:K,2,0) -> IR Declared due to CID -TA | R4: IR | S4: =VLOOKUP(R4,Sheet2!N:O,2,0) -> IREPARABLE | T4: =VLOOKUP(P4,Sheet2!Q:R,2,0) -> IR Normal - Track burn out | U4: IR CID - Tampered Track burn out | V4: 4 | W4: =VLOOKUP(V4,Sheet2!Q:R,2,0) -> IR CID - Tampered Track burn out | X4: =J4 -> A041 | Y4: =VLOOKUP(X4,Sheet2!A:B,2,0) -> PRASHANT,AKASH | Z4: UD1,U8,U10,R323,R7,R7 | AA4: 02.09.2021 | AB4: - | AC4: =LEFT(G4,2) -> 85 | AE4: HIMANSHU | CN4: NFF | CO4: SAMSUNG HD | CP4: SAMSUNG HD
A5: 3 | B5: 1009585251 | C5: 15.07.2021 | D5: W3.018 | E5: STANDBY | F5: Def Tag Available | G5: 854165770207 | H5: IR | I5: TECH HD | J5: A041 | K5: =VLOOKUP(J5,Sheet2!A:B,2,0) -> PRASHANT,AKASH | L5: 1 | M5: =VLOOKUP(L5,Sheet2!D:E,2,0) -> Power Supply Section | N5: 1 | O5: =VLOOKUP(N5,Sheet2!G:H,2,0) -> Dead | P5: 11 | Q5: =VLOOKUP(P5,Sheet2!J:K,2,0) -> IR Declared due to CID -TA | R5: IR | S5: =VLOOKUP(R5,Sheet2!N:O,2,0) -> IREPARABLE | T5: =VLOOKUP(P5,Sheet2!Q:R,2,0) -> IR Normal - Track burn out | U5: IR CID - Tampered Track burn out | V5: 4 | W5: =VLOOKUP(V5,Sheet2!Q:R,2,0) -> IR CID - Tampered Track burn out | X5: =J5 -> A041 | Y5: =VLOOKUP(X5,Sheet2!A:B,2,0) -> PRASHANT,AKASH | Z5: UD1,U8,U10 | AA5: 02.09.2021 | AB5: - | AC5: =LEFT(G5,2) -> 85 | AE5: HIMANSHU | CN5: SOAKING FAIL REPAIRED | CO5: TECH HD | CP5: TECH HD
A6: 4 | B6: 1005599968 | C6: 05.06.2021 | D6: W3.100 | E6: STANDBY | F6: Def Tag Available | G6: 844058781734 | H6: IR | I6: TECH HD | J6: A041 | K6: =VLOOKUP(J6,Sheet2!A:B,2,0) -> PRASHANT,AKASH | L6: 1 | M6: =VLOOKUP(L6,Sheet2!D:E,2,0) -> Power Supply Section | N6: 1 | O6: =VLOOKUP(N6,Sheet2!G:H,2,0) -> Dead | P6: 11 | Q6: =VLOOKUP(P6,Sheet2!J:K,2,0) -> IR Declared due to CID -TA | R6: IR | S6: =VLOOKUP(R6,Sheet2!N:O,2,0) -> IREPARABLE | T6: =VLOOKUP(P6,Sheet2!Q:R,2,0) -> IR Normal - Track burn out | U6: IR CID - Tampered Track burn out | V6: 4 | W6: =VLOOKUP(V6,Sheet2!Q:R,2,0) -> IR CID - Tampered Track burn out | X6: =J6 -> A041 | Y6: =VLOOKUP(X6,Sheet2!A:B,2,0) -> PRASHANT,AKASH | Z6: UD1,U8 | AA6: 02.09.2021 | AB6: - | AC6: =LEFT(G6,2) -> 84 | AE6: HIMANSHU | CN6: QC FAIL REPAIRED | CO6: PVR SD | CP6: PVR SD
A7: 5 | B7: 1009452143 | C7: 13.09.2021 | D7: NA | E7: DEAD | F7: Def Tag Available | G7: 853101739078 | H7: IR | I7: TECH HD | J7: A041 | K7: =VLOOKUP(J7,Sheet2!A:B,2,0) -> PRASHANT,AKASH | L7: 1 | M7: =VLOOKUP(L7,Sheet2!D:E,2,0) -> Power Supply Section | N7: 1 | O7: =VLOOKUP(N7,Sheet2!G:H,2,0) -> Dead | P7: 11 | Q7: =VLOOKUP(P7,Sheet2!J:K,2,0) -> IR Declared due to CID -TA | R7: IR | S7: =VLOOKUP(R7,Sheet2!N:O,2,0) -> IREPARABLE | T7: =VLOOKUP(P7,Sheet2!Q:R,2,0) -> IR Normal - Track burn out | U7: IR CID - Tampered Track burn out | V7: 4 | W7: =VLOOKUP(V7,Sheet2!Q:R,2,0) -> IR CID - Tampered Track burn out | X7: =J7 -> A041 | Y7: =VLOOKUP(X7,Sheet2!A:B,2,0) -> PRASHANT,AKASH | Z7: UD1,U8 | AA7: 02.09.2021 | AB7: - | AC7: =LEFT(G7,2) -> 85 | AE7: HIMANSHU | CN7: IMPEDENCE FAIL REPAIRED | CO7: PVR HD | CP7: PVR HD
A8: 6 | B8: 1009091247 | C8: 22.010.2020 | D8: NA | E8: DEAD | F8: Def Tag Available | G8: 853247759832 | H8: IR | I8: TECH HD | J8: A041 | K8: =VLOOKUP(J8,Sheet2!A:B,2,0) -> PRASHANT,AKASH | L8: 1 | M8: =VLOOKUP(L8,Sheet2!D:E,2,0) -> Power Supply Section | N8: 1 | O8: =VLOOKUP(N8,Sheet2!G:H,2,0) -> Dead | P8: 11 | Q8: =VLOOKUP(P8,Sheet2!J:K,2,0) -> IR Declared due to CID -TA | R8: IR | S8: =VLOOKUP(R8,Sheet2!N:O,2,0) -> IREPARABLE | T8: =VLOOKUP(P8,Sheet2!Q:R,2,0) -> IR Normal - Track burn out | U8: IR CID - Tampered Track burn out | V8: 4 | W8: =VLOOKUP(V8,Sheet2!Q:R,2,0) -> IR CID - Tampered Track burn out | X8: =J8 -> A041 | Y8: =VLOOKUP(X8,Sheet2!A:B,2,0) -> PRASHANT,AKASH | Z8: UD1,U8,U10,R323,R7,R7 | AA8: 02.09.2021 | AB8: - | AC8: =LEFT(G8,2) -> 85 | AE8: HIMANSHU | CN8: IR REPAIRED | CO8: JADE HD | CP8: JADE HD
A9: 7 | B9: 1009487179 | C9: 05.07.2021 | D9: NA | E9: NA | F9: NA(Tag Not Available) | G9: 854146798459 | H9: IR | I9: TECH HD | J9: A041 | K9: =VLOOKUP(J9,Sheet2!A:B,2,0) -> PRASHANT,AKASH | L9: 1 | M9: =VLOOKUP(L9,Sheet2!D:E,2,0) -> Power Supply Section | N9: 1 | O9: =VLOOKUP(N9,Sheet2!G:H,2,0) -> Dead | P9: 11 | Q9: =VLOOKUP(P9,Sheet2!J:K,2,0) -> IR Declared due to CID -TA | R9: IR | S9: =VLOOKUP(R9,Sheet2!N:O,2,0) -> IREPARABLE | T9: =VLOOKUP(P9,Sheet2!Q:R,2,0) -> IR Normal - Track burn out | U9: IR CID - Tampered Track burn out | V9: 4 | W9: =VLOOKUP(V9,Sheet2!Q:R,2,0) -> IR CID - Tampered Track burn out | X9: =J9 -> A041 | Y9: =VLOOKUP(X9,Sheet2!A:B,2,0) -> PRASHANT,AKASH | Z9: UD1,U8,U10 | AA9: 02.09.2021 | AB9: - | AC9: =LEFT(G9,2) -> 85 | AE9: HIMANSHU | CN9: COLD SOAK FAIL REPAIRED | CO9: NOVA HD | CP9: NOVA HD
A10: 8 | B10: 1009632811 | C10: 08.07.2021 | D10: NA | E10: DEAD | F10: Def Tag Available | G10: 844103735628 | H10: IR | I10: TECH HD | J10: A041 | K10: =VLOOKUP(J10,Sheet2!A:B,2,0) -> PRASHANT,AKASH | L10: 1 | M10: =VLOOKUP(L10,Sheet2!D:E,2,0) -> Power Supply Section | N10: 1 | O10: =VLOOKUP(N10,Sheet2!G:H,2,0) -> Dead | P10: 11 | Q10: =VLOOKUP(P10,Sheet2!J:K,2,0) -> IR Declared due to CID -TA | R10: IR | S10: =VLOOKUP(R10,Sheet2!N:O,2,0) -> IREPARABLE | T10: =VLOOKUP(P10,Sheet2!Q:R,2,0) -> IR Normal - Track burn out | U10: IR CID - Tampered Track burn out | V10: 4 | W10: =VLOOKUP(V10,Sheet2!Q:R,2,0) -> IR CID - Tampered Track burn out | X10: =J10 -> A041 | Y10: =VLOOKUP(X10,Sheet2!A:B,2,0) -> PRASHANT,AKASH | Z10: UD1,U8,U10 | AA10: 02.09.2021 | AB10: - | AC10: =LEFT(G10,2) -> 84 | AE10: HIMANSHU | CO10: T-51 | CP10: T-51
A11: 9 | B11: 1009091562 | C11: 24.05.2021 | D11: NA | E11: NA | F11: NA(Tag Not Available) | G11: 844042725771 | H11: IR | I11: TECH HD | J11: A041 | K11: =VLOOKUP(J11,Sheet2!A:B,2,0) -> PRASHANT,AKASH | L11: 1 | M11: =VLOOKUP(L11,Sheet2!D:E,2,0) -> Power Supply Section | N11: 1 | O11: =VLOOKUP(N11,Sheet2!G:H,2,0) -> Dead | P11: 11 | Q11: =VLOOKUP(P11,Sheet2!J:K,2,0) -> IR Declared due to CID -TA | R11: IR | S11: =VLOOKUP(R11,Sheet2!N:O,2,0) -> IREPARABLE | T11: =VLOOKUP(P11,Sheet2!Q:R,2,0) -> IR Normal - Track burn out | U11: IR CID - Tampered Track burn out | V11: 4 | W11: =VLOOKUP(V11,Sheet2!Q:R,2,0) -> IR CID - Tampered Track burn out | X11: =J11 -> A041 | Y11: =VLOOKUP(X11,Sheet2!A:B,2,0) -> PRASHANT,AKASH | Z11: UD1,U8,U10 | AA11: 02.09.2021 | AB11: - | AC11: =LEFT(G11,2) -> 84 | AE11: HIMANSHU | CO11: HEERA | CP11: HEERA
A12: 10 | B12: 1009630093 | C12: 20.06.2021 | D12: W3.028 | E12: DEAD | F12: Def Tag Available | G12: 853246771689 | H12: IR | I12: TECH HD | J12: A041 | K12: =VLOOKUP(J12,Sheet2!A:B,2,0) -> PRASHANT,AKASH | L12: 1 | M12: =VLOOKUP(L12,Sheet2!D:E,2,0) -> Power Supply Section | N12: 1 | O12: =VLOOKUP(N12,Sheet2!G:H,2,0) -> Dead | P12: 11 | Q12: =VLOOKUP(P12,Sheet2!J:K,2,0) -> IR Declared due to CID -TA | R12: IR | S12: =VLOOKUP(R12,Sheet2!N:O,2,0) -> IREPARABLE | T12: =VLOOKUP(P12,Sheet2!Q:R,2,0) -> IR Normal - Track burn out | U12: IR CID - Tampered Track burn out | V12: 4 | W12: =VLOOKUP(V12,Sheet2!Q:R,2,0) -> IR CID - Tampered Track burn out | X12: =J12 -> A041 | Y12: =VLOOKUP(X12,Sheet2!A:B,2,0) -> PRASHANT,AKASH | Z12: UD1,U8,U10 | AA12: 02.09.2021 | AB12: - | AC12: =LEFT(G12,2) -> 85 | AE12: HIMANSHU | CO12: PANNA | CP12: PANNA
A13: 11 | B13: 1009619637 | C13: 28.06.2021 | D13: E2.325 | E13: STANDBY | F13: Def Tag Available | G13: 844108707168 | H13: IR | I13: TECH HD | J13: A041 | K13: =VLOOKUP(J13,Sheet2!A:B,2,0) -> PRASHANT,AKASH | L13: 1 | M13: =VLOOKUP(L13,Sheet2!D:E,2,0) -> Power Supply Section | N13: 1 | O13: =VLOOKUP(N13,Sheet2!G:H,2,0) -> Dead | P13: 11 | Q13: =VLOOKUP(P13,Sheet2!J:K,2,0) -> IR Declared due to CID -TA | R13: IR | S13: =VLOOKUP(R13,Sheet2!N:O,2,0) -> IREPARABLE | T13: =VLOOKUP(P13,Sheet2!Q:R,2,0) -> IR Normal - Track burn out | U13: IR CID - Tampered Track burn out | V13: 4 | W13: =VLOOKUP(V13,Sheet2!Q:R,2,0) -> IR CID - Tampered Track burn out | X13: =J13 -> A041 | Y13: =VLOOKUP(X13,Sheet2!A:B,2,0) -> PRASHANT,AKASH | Z13: UD1,U8,U10 | AA13: 02.09.2021 | AB13: - | AC13: =LEFT(G13,2) -> 84 | AE13: HIMANSHU | CO13: SKY WORTH | CP13: SKY WORTH
A14: 12 | B14: 1009635715 | C14: 22.04.2021 | D14: NA | E14: DEAD | F14: Def Tag Available | G14: 853039700903 | H14: IR | I14: TECH HD | J14: A041 | K14: =VLOOKUP(J14,Sheet2!A:B,2,0) -> PRASHANT,AKASH | L14: 1 | M14: =VLOOKUP(L14,Sheet2!D:E,2,0) -> Power Supply Section | N14: 1 | O14: =VLOOKUP(N14,Sheet2!G:H,2,0) -> Dead | P14: 11 | Q14: =VLOOKUP(P14,Sheet2!J:K,2,0) -> IR Declared due to CID -TA | R14: IR | S14: =VLOOKUP(R14,Sheet2!N:O,2,0) -> IREPARABLE | T14: =VLOOKUP(P14,Sheet2!Q:R,2,0) -> IR Normal - Track burn out | U14: IR CID - Tampered Track burn out | V14: 4 | W14: =VLOOKUP(V14,Sheet2!Q:R,2,0) -> IR CID - Tampered Track burn out | X14: =J14 -> A041 | Y14: =VLOOKUP(X14,Sheet2!A:B,2,0) -> PRASHANT,AKASH | Z14: UD1,U8,U10 | AA14: 02.09.2021 | AB14: - | AC14: =LEFT(G14,2) -> 85 | AE14: HIMANSHU | CO14: BINGE | CP14: BINGE
A15: 13 | B15: 1009616146 | C15: 02.06.2021 | D15: W3.087 | E15: DEAD | F15: Def Tag Available | G15: 853253707378 | H15: IR | I15: TECH HD | J15: A041 | K15: =VLOOKUP(J15,Sheet2!A:B,2,0) -> PRASHANT,AKASH | L15: 1 | M15: =VLOOKUP(L15,Sheet2!D:E,2,0) -> Power Supply Section | N15: 1 | O15: =VLOOKUP(N15,Sheet2!G:H,2,0) -> Dead | P15: 11 | Q15: =VLOOKUP(P15,Sheet2!J:K,2,0) -> IR Declared due to CID -TA | R15: IR | S15: =VLOOKUP(R15,Sheet2!N:O,2,0) -> IREPARABLE | T15: =VLOOKUP(P15,Sheet2!Q:R,2,0) -> IR Normal - Track burn out | U15: IR CID - Tampered Track burn out | V15: 4 | W15: =VLOOKUP(V15,Sheet2!Q:R,2,0) -> IR CID - Tampered Track burn out | X15: =J15 -> A041 | Y15: =VLOOKUP(X15,Sheet2!A:B,2,0) -> PRASHANT,AKASH | Z15: UD1,U8,U10 | AA15: 02.09.2021 | AB15: - | AC15: =LEFT(G15,2) -> 85 | AE15: HIMANSHU
A16: 14 | B16: 1009616645 | C16: 09.06.2021 | D16: W3.013 | E16: DEAD | F16: Def Tag Available | G16: 844087721354 | H16: IR | I16: TECH HD | J16: A041 | K16: =VLOOKUP(J16,Sheet2!A:B,2,0) -> PRASHANT,AKASH | L16: 1 | M16: =VLOOKUP(L16,Sheet2!D:E,2,0) -> Power Supply Section | N16: 1 | O16: =VLOOKUP(N16,Sheet2!G:H,2,0) -> Dead | P16: 11 | Q16: =VLOOKUP(P16,Sheet2!J:K,2,0) -> IR Declared due to CID -TA | R16: IR | S16: =VLOOKUP(R16,Sheet2!N:O,2,0) -> IREPARABLE | T16: =VLOOKUP(P16,Sheet2!Q:R,2,0) -> IR Normal - Track burn out | U16: IR CID - Tampered Track burn out | V16: 4 | W16: =VLOOKUP(V16,Sheet2!Q:R,2,0) -> IR CID - Tampered Track burn out | X16: =J16 -> A041 | Y16: =VLOOKUP(X16,Sheet2!A:B,2,0) -> PRASHANT,AKASH | Z16: UD1,U8,U10 | AA16: 02.09.2021 | AB16: - | AC16: =LEFT(G16,2) -> 84 | AE16: HIMANSHU
A17: 15 | B17: 1009477026 | C17: 16.03.2020 | D17: NA | E17: DEAD | F17: Def Tag Available | G17: 844060793024 | H17: IR | I17: TECH HD | J17: A041 | K17: =VLOOKUP(J17,Sheet2!A:B,2,0) -> PRASHANT,AKASH | L17: 1 | M17: =VLOOKUP(L17,Sheet2!D:E,2,0) -> Power Supply Section | N17: 1 | O17: =VLOOKUP(N17,Sheet2!G:H,2,0) -> Dead | P17: 11 | Q17: =VLOOKUP(P17,Sheet2!J:K,2,0) -> IR Declared due to CID -TA | R17: IR | S17: =VLOOKUP(R17,Sheet2!N:O,2,0) -> IREPARABLE | T17: =VLOOKUP(P17,Sheet2!Q:R,2,0) -> IR Normal - Track burn out | U17: IR CID - Tampered Track burn out | V17: 4 | W17: =VLOOKUP(V17,Sheet2!Q:R,2,0) -> IR CID - Tampered Track burn out | X17: =J17 -> A041 | Y17: =VLOOKUP(X17,Sheet2!A:B,2,0) -> PRASHANT,AKASH | Z17: UD1,U8,U10 | AA17: 02.09.2021 | AB17: - | AC17: =LEFT(G17,2) -> 84 | AE17: HIMANSHU
A18: 16 | B18: 1009630941 | C18: 26.07.2021 | D18: NA | E18: UPGRADE | F18: Upgrade Tag Available | G18: 844084748111 | H18: IR | I18: TECH HD | J18: A041 | K18: =VLOOKUP(J18,Sheet2!A:B,2,0) -> PRASHANT,AKASH | L18: 1 | M18: =VLOOKUP(L18,Sheet2!D:E,2,0) -> Power Supply Section | N18: 1 | O18: =VLOOKUP(N18,Sheet2!G:H,2,0) -> Dead | P18: 11 | Q18: =VLOOKUP(P18,Sheet2!J:K,2,0) -> IR Declared due to CID -TA | R18: IR | S18: =VLOOKUP(R18,Sheet2!N:O,2,0) -> IREPARABLE | T18: =VLOOKUP(P18,Sheet2!Q:R,2,0) -> IR Normal - Track burn out | U18: IR CID - Tampered Track burn out | V18: 4 | W18: =VLOOKUP(V18,Sheet2!Q:R,2,0) -> IR CID - Tampered Track burn out | X18: =J18 -> A041 | Y18: =VLOOKUP(X18,Sheet2!A:B,2,0) -> PRASHANT,AKASH | Z18: UD1,U8,U10 | AA18: 02.09.2021 | AB18: - | AC18: =LEFT(G18,2) -> 84 | AE18: HIMANSHU
A19: 17 | B19: 1009621043 | C19: 09.08.2021 | D19: NA | E19: STANDBY | F19: Def Tag Available | G19: `844021749610 | H19: IR | I19: TECH HD | J19: A041 | K19: =VLOOKUP(J19,Sheet2!A:B,2,0) -> PRASHANT,AKASH | L19: 1 | M19: =VLOOKUP(L19,Sheet2!D:E,2,0) -> Power Supply Section | N19: 1 | O19: =VLOOKUP(N19,Sheet2!G:H,2,0) -> Dead | P19: 11 | Q19: =VLOOKUP(P19,Sheet2!J:K,2,0) -> IR Declared due to CID -TA | R19: IR | S19: =VLOOKUP(R19,Sheet2!N:O,2,0) -> IREPARABLE | T19: =VLOOKUP(P19,Sheet2!Q:R,2,0) -> IR Normal - Track burn out | U19: IR CID - Tampered Track burn out | V19: 4 | W19: =VLOOKUP(V19,Sheet2!Q:R,2,0) -> IR CID - Tampered Track burn out | X19: =J19 -> A041 | Y19: =VLOOKUP(X19,Sheet2!A:B,2,0) -> PRASHANT,AKASH | Z19: UD1,U8,U10 | AA19: 02.09.2021 | AB19: - | AC19: =LEFT(G19,2) -> `8 | AE19: HIMANSHU
A20: 18 | B20: 1009091859 | C20: 05.08.2021 | D20: NA | E20: DEAD | F20: Def Tag Available | G20: 867066142433 | H20: IR | I20: NOVA HD | J20: A004 | K20: =VLOOKUP(J20,Sheet2!A:B,2,0) -> JAYESH NAI | L20: 5 | M20: =VLOOKUP(L20,Sheet2!D:E,2,0) -> Main Processor CPU BGA | N20: 24 | O20: =VLOOKUP(N20,Sheet2!G:H,2,0) -> STB Auto moving -Stand by mode | P20: 12 | Q20: =VLOOKUP(P20,Sheet2!J:K,2,0) -> IR Declared due to Others ( IR Normal)TB | R20: IR | S20: =VLOOKUP(R20,Sheet2!N:O,2,0) -> IREPARABLE | T20: =VLOOKUP(P20,Sheet2!Q:R,2,0) -> IR Normal - BER to IR | U20: IR CID - Tampered Track burn out | V20: 11 | W20: =VLOOKUP(V20,Sheet2!Q:R,2,0) -> IR Normal - Track burn out | X20: =J20 -> A004 | Y20: =VLOOKUP(X20,Sheet2!A:B,2,0) -> JAYESH NAI | Z20: RP004,RP005 | AA20: 02.09.2021 | AB20: - | AC20: =LEFT(G20,2) -> 86 | AE20: HIMANSHU
A21: 19 | B21: 1009623399 | C21: 09.04.2021 | D21: NA | E21: ERROR1 | F21: Def Tag Available | G21: 866293131110 | H21: IR | I21: NOVA HD | J21: A050 | K21: =VLOOKUP(J21,Sheet2!A:B,2,0) -> PIYUSH CHAVDA | L21: 1 | M21: =VLOOKUP(L21,Sheet2!D:E,2,0) -> Power Supply Section | N21: 1 | O21: =VLOOKUP(N21,Sheet2!G:H,2,0) -> Dead | P21: 12 | Q21: =VLOOKUP(P21,Sheet2!J:K,2,0) -> IR Declared due to Others ( IR Normal)TB | R21: IR | S21: =VLOOKUP(R21,Sheet2!N:O,2,0) -> IREPARABLE | T21: =VLOOKUP(P21,Sheet2!Q:R,2,0) -> IR Normal - BER to IR | U21: IR Normal -TrackRust/InternalDamage/open | V21: 8 | W21: =VLOOKUP(V21,Sheet2!Q:R,2,0) -> IR Normal -TrackRust/InternalDamage/open | X21: =J21 -> A050 | Y21: =VLOOKUP(X21,Sheet2!A:B,2,0) -> PIYUSH CHAVDA | Z21: RP004,RP005 | AA21: 02.09.2021 | AB21: - | AC21: =LEFT(G21,2) -> 86 | AE21: HIMANSHU
A22: 20 | B22: 1009623386 | C22: 20.08.2021 | D22: W3.206 | E22: DEAD | F22: Def Tag Available | G22: 866174115497 | H22: IR | I22: NOVA HD | J22: A050 | K22: =VLOOKUP(J22,Sheet2!A:B,2,0) -> PIYUSH CHAVDA | L22: 5 | M22: =VLOOKUP(L22,Sheet2!D:E,2,0) -> Main Processor CPU BGA | N22: 24 | O22: =VLOOKUP(N22,Sheet2!G:H,2,0) -> STB Auto moving -Stand by mode | P22: 12 | Q22: =VLOOKUP(P22,Sheet2!J:K,2,0) -> IR Declared due to Others ( IR Normal)TB | R22: IR | S22: =VLOOKUP(R22,Sheet2!N:O,2,0) -> IREPARABLE | T22: =VLOOKUP(P22,Sheet2!Q:R,2,0) -> IR Normal - BER to IR | U22: IR Normal -TrackRust/InternalDamage/open | V22: 8 | W22: =VLOOKUP(V22,Sheet2!Q:R,2,0) -> IR Normal -TrackRust/InternalDamage/open | X22: =J22 -> A050 | Y22: =VLOOKUP(X22,Sheet2!A:B,2,0) -> PIYUSH CHAVDA | Z22: RP004,RP005 | AA22: 02.09.2021 | AB22: - | AC22: =LEFT(G22,2) -> 86 | AE22: HIMANSHU
A23: 21 | B23: 1009606821 | C23: 21.08.2021 | D23: W3.003 | E23: DEAD | F23: Def Tag Available | G23: 865133116190 | H23: IR | I23: NOVA HD | J23: A018 | K23: =VLOOKUP(J23,Sheet2!A:B,2,0) -> PRAKASH CHAVDA | L23: 1 | M23: =VLOOKUP(L23,Sheet2!D:E,2,0) -> Power Supply Section | N23: 1 | O23: =VLOOKUP(N23,Sheet2!G:H,2,0) -> Dead | P23: 11 | Q23: =VLOOKUP(P23,Sheet2!J:K,2,0) -> IR Declared due to CID -TA | R23: IR | S23: =VLOOKUP(R23,Sheet2!N:O,2,0) -> IREPARABLE | T23: =VLOOKUP(P23,Sheet2!Q:R,2,0) -> IR Normal - Track burn out | U23: IR CID - Tampered Track burn out | V23: 4 | W23: =VLOOKUP(V23,Sheet2!Q:R,2,0) -> IR CID - Tampered Track burn out | X23: =J23 -> A018 | Y23: =VLOOKUP(X23,Sheet2!A:B,2,0) -> PRAKASH CHAVDA | Z23: UP098,UA001 | AA23: 02.09.2021 | AB23: - | AC23: =LEFT(G23,2) -> 86 | AE23: HIMANSHU
A24: 22 | B24: 1009619650 | C24: 20.08.2021 | D24: W3.083 | E24: VIDEO PROBLEM | F24: Def Tag Available | G24: 867231182777 | H24: IR | I24: NOVA HD | J24: A050 | K24: =VLOOKUP(J24,Sheet2!A:B,2,0) -> PIYUSH CHAVDA | L24: 1 | M24: =VLOOKUP(L24,Sheet2!D:E,2,0) -> Power Supply Section | N24: 1 | O24: =VLOOKUP(N24,Sheet2!G:H,2,0) -> Dead | P24: 12 | Q24: =VLOOKUP(P24,Sheet2!J:K,2,0) -> IR Declared due to Others ( IR Normal)TB | R24: IR | S24: =VLOOKUP(R24,Sheet2!N:O,2,0) -> IREPARABLE | T24: =VLOOKUP(P24,Sheet2!Q:R,2,0) -> IR Normal - BER to IR | U24: IR Normal - Multiple time repair | V24: 9 | W24: =VLOOKUP(V24,Sheet2!Q:R,2,0) -> IR Normal - Multiple time repair | X24: =J24 -> A050 | Y24: =VLOOKUP(X24,Sheet2!A:B,2,0) -> PIYUSH CHAVDA | Z24: NA | AA24: 02.09.2021 | AB24: - | AC24: =LEFT(G24,2) -> 86 | AE24: HIMANSHU
A25: 23 | B25: 1009555613 | C25: 21.08.2021 | D25: NA | E25: NA | F25: NA(Tag Not Available) | G25: 867150113662 | H25: IR | I25: NOVA HD | J25: A031 | K25: =VLOOKUP(J25,Sheet2!A:B,2,0) -> NITIN PRANAMI | L25: 5 | M25: =VLOOKUP(L25,Sheet2!D:E,2,0) -> Main Processor CPU BGA | N25: 1 | O25: =VLOOKUP(N25,Sheet2!G:H,2,0) -> Dead | P25: 12 | Q25: =VLOOKUP(P25,Sheet2!J:K,2,0) -> IR Declared due to Others ( IR Normal)TB | R25: IR | S25: =VLOOKUP(R25,Sheet2!N:O,2,0) -> IREPARABLE | T25: =VLOOKUP(P25,Sheet2!Q:R,2,0) -> IR Normal - BER to IR | U25: IR Normal -TrackRust/InternalDamage/open | V25: 8 | W25: =VLOOKUP(V25,Sheet2!Q:R,2,0) -> IR Normal -TrackRust/InternalDamage/open | X25: =J25 -> A031 | Y25: =VLOOKUP(X25,Sheet2!A:B,2,0) -> NITIN PRANAMI | Z25: UV001,UA001,UP098,UN001 | AA25: 02.09.2021 | AB25: - | AC25: =LEFT(G25,2) -> 86 | AE25: HIMANSHU
A26: 24 | B26: 1009631412 | C26: 21.08.2021 | D26: W3.218 | E26: NO SIGNAL | F26: Def Tag Available | G26: 868113119721 | H26: IR | I26: NOVA HD | J26: A042 | K26: =VLOOKUP(J26,Sheet2!A:B,2,0) -> ANKIT RANA | L26: 5 | M26: =VLOOKUP(L26,Sheet2!D:E,2,0) -> Main Processor CPU BGA | N26: 24 | O26: =VLOOKUP(N26,Sheet2!G:H,2,0) -> STB Auto moving -Stand by mode | P26: 12 | Q26: =VLOOKUP(P26,Sheet2!J:K,2,0) -> IR Declared due to Others ( IR Normal)TB | R26: IR | S26: =VLOOKUP(R26,Sheet2!N:O,2,0) -> IREPARABLE | T26: =VLOOKUP(P26,Sheet2!Q:R,2,0) -> IR Normal - BER to IR | U26: IR Normal -TrackRust/InternalDamage/open | V26: 8 | W26: =VLOOKUP(V26,Sheet2!Q:R,2,0) -> IR Normal -TrackRust/InternalDamage/open | X26: =J26 -> A042 | Y26: =VLOOKUP(X26,Sheet2!A:B,2,0) -> ANKIT RANA | Z26: UV001,UA001,UP098,UN001 | AA26: 02.09.2021 | AB26: - | AC26: =LEFT(G26,2) -> 86 | AE26: HIMANSHU
A27: 25 | B27: 1007461577 | C27: 21.08.201 | D27: W3.0180 | E27: DEAD | F27: Def Tag Available | G27: 864285114715 | H27: IR | I27: NOVA HD | J27: A053 | K27: =VLOOKUP(J27,Sheet2!A:B,2,0) -> DEVENDRA RAJPUT | L27: 5 | M27: =VLOOKUP(L27,Sheet2!D:E,2,0) -> Main Processor CPU BGA | N27: 1 | O27: =VLOOKUP(N27,Sheet2!G:H,2,0) -> Dead | P27: 12 | Q27: =VLOOKUP(P27,Sheet2!J:K,2,0) -> IR Declared due to Others ( IR Normal)TB | R27: IR | S27: =VLOOKUP(R27,Sheet2!N:O,2,0) -> IREPARABLE | T27: =VLOOKUP(P27,Sheet2!Q:R,2,0) -> IR Normal - BER to IR | U27: IR Normal -TrackRust/InternalDamage/open | V27: 8 | W27: =VLOOKUP(V27,Sheet2!Q:R,2,0) -> IR Normal -TrackRust/InternalDamage/open | X27: =J27 -> A053 | Y27: =VLOOKUP(X27,Sheet2!A:B,2,0) -> DEVENDRA RAJPUT | Z27: UV001,UA001,UP098,UN001 | AA27: 02.09.2021 | AB27: - | AC27: =LEFT(G27,2) -> 86 | AE27: HIMANSHU
A28: 26 | B28: 1009091534 | C28: 20.08.2021 | D28: W3.007 | E28: STANDBY | F28: Def Tag Available | G28: 865276369564 | H28: IR | I28: NOVA HD | J28: A031 | K28: =VLOOKUP(J28,Sheet2!A:B,2,0) -> NITIN PRANAMI | L28: 1 | M28: =VLOOKUP(L28,Sheet2!D:E,2,0) -> Power Supply Section | N28: 1 | O28: =VLOOKUP(N28,Sheet2!G:H,2,0) -> Dead | P28: 11 | Q28: =VLOOKUP(P28,Sheet2!J:K,2,0) -> IR Declared due to CID -TA | R28: IR | S28: =VLOOKUP(R28,Sheet2!N:O,2,0) -> IREPARABLE | T28: =VLOOKUP(P28,Sheet2!Q:R,2,0) -> IR Normal - Track burn out | U28: IR CID -Fullydamage-Broken/Dent/Burn out | V28: 6 | W28: =VLOOKUP(V28,Sheet2!Q:R,2,0) -> IR CID -Fullydamage-Broken/Dent/Burn out | X28: =J28 -> A031 | Y28: =VLOOKUP(X28,Sheet2!A:B,2,0) -> NITIN PRANAMI | Z28: UV001,UA001,UP098,UN001 | AA28: 02.09.2021 | AB28: - | AC28: =LEFT(G28,2) -> 86 | AE28: HIMANSHU
A29: 27 | B29: 1009443831 | C29: 20.08.2021 | D29: NA | E29: NA | F29: NA(Tag Not Available) | G29: 986018177261 | H29: IR | I29: STD | J29: A063 | K29: =VLOOKUP(J29,Sheet2!A:B,2,0) -> SHANI GOHIL | L29: 7 | M29: =VLOOKUP(L29,Sheet2!D:E,2,0) -> Card Reader Section | N29: 37 | O29: =VLOOKUP(N29,Sheet2!G:H,2,0) -> Error -2 | P29: 11 | Q29: =VLOOKUP(P29,Sheet2!J:K,2,0) -> IR Declared due to CID -TA | R29: IR | S29: =VLOOKUP(R29,Sheet2!N:O,2,0) -> IREPARABLE | T29: =VLOOKUP(P29,Sheet2!Q:R,2,0) -> IR Normal - Track burn out | U29: IR CID - Water log from other area | V29: 2 | W29: =VLOOKUP(V29,Sheet2!Q:R,2,0) -> IR CID - Water log from other area | X29: =J29 -> A063 | Y29: =VLOOKUP(X29,Sheet2!A:B,2,0) -> SHANI GOHIL | Z29: LP041,CX014 | AA29: 02.09.2021 | AB29: - | AC29: =LEFT(G29,2) -> 98 | AE29: HIMANSHU
A30: 28 | B30: 1009616633 | C30: 21.08.2021 | D30: NA | E30: NA | F30: NA(Tag Not Available) | G30: 987200107215 | H30: IR | I30: STD | J30: A063 | K30: =VLOOKUP(J30,Sheet2!A:B,2,0) -> SHANI GOHIL | L30: 1 | M30: =VLOOKUP(L30,Sheet2!D:E,2,0) -> Power Supply Section | N30: 1 | O30: =VLOOKUP(N30,Sheet2!G:H,2,0) -> Dead | P30: 11 | Q30: =VLOOKUP(P30,Sheet2!J:K,2,0) -> IR Declared due to CID -TA | R30: IR | S30: =VLOOKUP(R30,Sheet2!N:O,2,0) -> IREPARABLE | T30: =VLOOKUP(P30,Sheet2!Q:R,2,0) -> IR Normal - Track burn out | U30: IR CID - Water log from other area | V30: 2 | W30: =VLOOKUP(V30,Sheet2!Q:R,2,0) -> IR CID - Water log from other area | X30: =J30 -> A063 | Y30: =VLOOKUP(X30,Sheet2!A:B,2,0) -> SHANI GOHIL | Z30: UP006,UN016 | AA30: 02.09.2021 | AB30: - | AC30: =LEFT(G30,2) -> 98 | AE30: HIMANSHU
A31: 29 | B31: 1009625934 | C31: 21.08.2021 | D31: NA | E31: NA | F31: NA(Tag Not Available) | G31: 987235209879 | H31: IR | I31: STD | J31: A063 | K31: =VLOOKUP(J31,Sheet2!A:B,2,0) -> SHANI GOHIL | L31: 7 | M31: =VLOOKUP(L31,Sheet2!D:E,2,0) -> Card Reader Section | N31: 36 | O31: =VLOOKUP(N31,Sheet2!G:H,2,0) -> Error -1 | P31: 11 | Q31: =VLOOKUP(P31,Sheet2!J:K,2,0) -> IR Declared due to CID -TA | R31: IR | S31: =VLOOKUP(R31,Sheet2!N:O,2,0) -> IREPARABLE | T31: =VLOOKUP(P31,Sheet2!Q:R,2,0) -> IR Normal - Track burn out | U31: IR CID - Tampered Track burn out | V31: 4 | W31: =VLOOKUP(V31,Sheet2!Q:R,2,0) -> IR CID - Tampered Track burn out | X31: =J31 -> A063 | Y31: =VLOOKUP(X31,Sheet2!A:B,2,0) -> SHANI GOHIL | Z31: UX001 | AA31: 02.09.2021 | AB31: - | AC31: =LEFT(G31,2) -> 98 | AE31: HIMANSHU
A32: 30 | B32: 1009628154 | C32: 14.08.2021 | D32: NA | E32: NA | F32: NA(Tag Not Available) | G32: 942102965301 | H32: IR | I32: STD | J32: A063 | K32: =VLOOKUP(J32,Sheet2!A:B,2,0) -> SHANI GOHIL | L32: 1 | M32: =VLOOKUP(L32,Sheet2!D:E,2,0) -> Power Supply Section | N32: 2 | O32: =VLOOKUP(N32,Sheet2!G:H,2,0) -> Dead Intermittent | P32: 12 | Q32: =VLOOKUP(P32,Sheet2!J:K,2,0) -> IR Declared due to Others ( IR Normal)TB | R32: IR | S32: =VLOOKUP(R32,Sheet2!N:O,2,0) -> IREPARABLE | T32: =VLOOKUP(P32,Sheet2!Q:R,2,0) -> IR Normal - BER to IR | U32: IR Normal - Multiple time repair | V32: 9 | W32: =VLOOKUP(V32,Sheet2!Q:R,2,0) -> IR Normal - Multiple time repair | X32: =J32 -> A063 | Y32: =VLOOKUP(X32,Sheet2!A:B,2,0) -> SHANI GOHIL | Z32: UD1 | AA32: 02.09.2021 | AB32: - | AC32: =LEFT(G32,2) -> 94 | AE32: HIMANSHU
A33: =1+A32 -> 31 | B33: 1009565314 | C33: 20.08.2021 | D33: NA | E33: NA | F33: NA(Tag Not Available) | G33: 943164962897 | H33: IR | I33: STD | J33: A031 | K33: =VLOOKUP(J33,Sheet2!A:B,2,0) -> NITIN PRANAMI | L33: 1 | M33: =VLOOKUP(L33,Sheet2!D:E,2,0) -> Power Supply Section | N33: 24 | O33: =VLOOKUP(N33,Sheet2!G:H,2,0) -> STB Auto moving -Stand by mode | P33: 12 | Q33: =VLOOKUP(P33,Sheet2!J:K,2,0) -> IR Declared due to Others ( IR Normal)TB | R33: IR | S33: =VLOOKUP(R33,Sheet2!N:O,2,0) -> IREPARABLE | T33: =VLOOKUP(P33,Sheet2!Q:R,2,0) -> IR Normal - BER to IR | U33: IR Normal -TrackRust/InternalDamage/open | V33: 8 | W33: =VLOOKUP(V33,Sheet2!Q:R,2,0) -> IR Normal -TrackRust/InternalDamage/open | X33: =J33 -> A031 | Y33: =VLOOKUP(X33,Sheet2!A:B,2,0) -> NITIN PRANAMI | Z33: U1,U5,U6,U4,U5,U12,U14 | AA33: 02.09.2021 | AB33: - | AC33: =LEFT(G33,2) -> 94 | AE33: HIMANSHU
A34: =1+A33 -> 32 | B34: 1009570945 | C34: 20.08.2021 | D34: W3.018 | E34: UPGRADE | F34: Upgrade Tag Available | G34: 954319131809 | H34: IR | I34: STD | J34: A063 | K34: =VLOOKUP(J34,Sheet2!A:B,2,0) -> SHANI GOHIL | L34: 5 | M34: =VLOOKUP(L34,Sheet2!D:E,2,0) -> Main Processor CPU BGA | N34: 24 | O34: =VLOOKUP(N34,Sheet2!G:H,2,0) -> STB Auto moving -Stand by mode | P34: 12 | Q34: =VLOOKUP(P34,Sheet2!J:K,2,0) -> IR Declared due to Others ( IR Normal)TB | R34: IR | S34: =VLOOKUP(R34,Sheet2!N:O,2,0) -> IREPARABLE | T34: =VLOOKUP(P34,Sheet2!Q:R,2,0) -> IR Normal - BER to IR | U34: IR Normal -TrackRust/InternalDamage/open | V34: 8 | W34: =VLOOKUP(V34,Sheet2!Q:R,2,0) -> IR Normal -TrackRust/InternalDamage/open | X34: =J34 -> A063 | Y34: =VLOOKUP(X34,Sheet2!A:B,2,0) -> SHANI GOHIL | Z34: U300,U304,U307,U1000 | AA34: 02.09.2021 | AB34: - | AC34: =LEFT(G34,2) -> 95 | AE34: HIMANSHU
A35: =1+A34 -> 33 | B35: 1009574505 | C35: 21.08.2021 | D35: NA | E35: STANDBY | F35: Def Tag Available | G35: 775240041456 | H35: IR | I35: JADE HD | J35: A050 | K35: =VLOOKUP(J35,Sheet2!A:B,2,0) -> PIYUSH CHAVDA | L35: 1 | M35: =VLOOKUP(L35,Sheet2!D:E,2,0) -> Power Supply Section | N35: 24 | O35: =VLOOKUP(N35,Sheet2!G:H,2,0) -> STB Auto moving -Stand by mode | P35: 12 | Q35: =VLOOKUP(P35,Sheet2!J:K,2,0) -> IR Declared due to Others ( IR Normal)TB | R35: IR | S35: =VLOOKUP(R35,Sheet2!N:O,2,0) -> IREPARABLE | T35: =VLOOKUP(P35,Sheet2!Q:R,2,0) -> IR Normal - BER to IR | U35: IR CID - Tampered Track burn out | V35: 11 | W35: =VLOOKUP(V35,Sheet2!Q:R,2,0) -> IR Normal - Track burn out | X35: =J35 -> A050 | Y35: =VLOOKUP(X35,Sheet2!A:B,2,0) -> PIYUSH CHAVDA | Z35: U502 | AA35: 02.09.2021 | AB35: - | AC35: =LEFT(G35,2) -> 77 | AE35: HIMANSHU
A36: =1+A35 -> 34 | B36: 1009569924 | C36: 20.08.2021 | D36: W3.030 | E36: STANDBY | F36: Def Tag Available | G36: 775318176895 | H36: IR | I36: JADE HD | J36: A031 | K36: =VLOOKUP(J36,Sheet2!A:B,2,0) -> NITIN PRANAMI | L36: 1 | M36: =VLOOKUP(L36,Sheet2!D:E,2,0) -> Power Supply Section | N36: 24 | O36: =VLOOKUP(N36,Sheet2!G:H,2,0) -> STB Auto moving -Stand by mode | P36: 12 | Q36: =VLOOKUP(P36,Sheet2!J:K,2,0) -> IR Declared due to Others ( IR Normal)TB | R36: IR | S36: =VLOOKUP(R36,Sheet2!N:O,2,0) -> IREPARABLE | T36: =VLOOKUP(P36,Sheet2!Q:R,2,0) -> IR Normal - BER to IR | U36: IR Normal -TrackRust/InternalDamage/open | V36: 8 | W36: =VLOOKUP(V36,Sheet2!Q:R,2,0) -> IR Normal -TrackRust/InternalDamage/open | X36: =J36 -> A031 | Y36: =VLOOKUP(X36,Sheet2!A:B,2,0) -> NITIN PRANAMI | Z36: U1103,U1104,U502,J6 | AA36: 02.09.2021 | AB36: - | AC36: =LEFT(G36,2) -> 77 | AE36: HIMANSHU
A37: =1+A36 -> 35 | B37: 1009571192 | C37: 20.08.2021 | D37: W3.031 | E37: DEAD | F37: Def Tag Available | G37: 775335236888 | H37: IR | I37: JADE HD | J37: A031 | K37: =VLOOKUP(J37,Sheet2!A:B,2,0) -> NITIN PRANAMI | L37: 1 | M37: =VLOOKUP(L37,Sheet2!D:E,2,0) -> Power Supply Section | N37: 1 | O37: =VLOOKUP(N37,Sheet2!G:H,2,0) -> Dead | P37: 12 | Q37: =VLOOKUP(P37,Sheet2!J:K,2,0) -> IR Declared due to Others ( IR Normal)TB | R37: IR | S37: =VLOOKUP(R37,Sheet2!N:O,2,0) -> IREPARABLE | T37: =VLOOKUP(P37,Sheet2!Q:R,2,0) -> IR Normal - BER to IR | U37: IR Normal -TrackRust/InternalDamage/open | V37: 8 | W37: =VLOOKUP(V37,Sheet2!Q:R,2,0) -> IR Normal -TrackRust/InternalDamage/open | X37: =J37 -> A031 | Y37: =VLOOKUP(X37,Sheet2!A:B,2,0) -> NITIN PRANAMI | Z37: U1103,U1104,U502,J6 | AA37: 02.09.2021 | AB37: - | AC37: =LEFT(G37,2) -> 77 | AE37: HIMANSHU
A38: =1+A37 -> 36 | B38: 1009573534 | C38: 21.08.2021 | D38: NA | E38: DEAD | F38: Def Tag Available | G38: 775322107969 | H38: IR | I38: JADE HD | J38: A009 | K38: =VLOOKUP(J38,Sheet2!A:B,2,0) -> AKASH BAROT | L38: 1 | M38: =VLOOKUP(L38,Sheet2!D:E,2,0) -> Power Supply Section | N38: 1 | O38: =VLOOKUP(N38,Sheet2!G:H,2,0) -> Dead | P38: 12 | Q38: =VLOOKUP(P38,Sheet2!J:K,2,0) -> IR Declared due to Others ( IR Normal)TB | R38: IR | S38: =VLOOKUP(R38,Sheet2!N:O,2,0) -> IREPARABLE | T38: =VLOOKUP(P38,Sheet2!Q:R,2,0) -> IR Normal - BER to IR | U38: IR CID - Tampered Track burn out | V38: 11 | W38: =VLOOKUP(V38,Sheet2!Q:R,2,0) -> IR Normal - Track burn out | X38: =J38 -> A009 | Y38: =VLOOKUP(X38,Sheet2!A:B,2,0) -> AKASH BAROT | Z38: U502 | AA38: 02.09.2021 | AB38: - | AC38: =LEFT(G38,2) -> 77 | AE38: HIMANSHU
A39: =1+A38 -> 37 | B39: 1009567138 | C39: 20.08.2021 | D39: W3.007 | E39: STANDBY | F39: Def Tag Available | G39: 775156036870 | H39: IR | I39: JADE HD | J39: A053 | K39: =VLOOKUP(J39,Sheet2!A:B,2,0) -> DEVENDRA RAJPUT | L39: 1 | M39: =VLOOKUP(L39,Sheet2!D:E,2,0) -> Power Supply Section | N39: 1 | O39: =VLOOKUP(N39,Sheet2!G:H,2,0) -> Dead | P39: 12 | Q39: =VLOOKUP(P39,Sheet2!J:K,2,0) -> IR Declared due to Others ( IR Normal)TB | R39: IR | S39: =VLOOKUP(R39,Sheet2!N:O,2,0) -> IREPARABLE | T39: =VLOOKUP(P39,Sheet2!Q:R,2,0) -> IR Normal - BER to IR | U39: IR CID - Tampered Track burn out | V39: 11 | W39: =VLOOKUP(V39,Sheet2!Q:R,2,0) -> IR Normal - Track burn out | X39: =J39 -> A053 | Y39: =VLOOKUP(X39,Sheet2!A:B,2,0) -> DEVENDRA RAJPUT | Z39: U502 | AA39: 02.09.2021 | AB39: - | AC39: =LEFT(G39,2) -> 77 | AE39: HIMANSHU
A40: =1+A39 -> 38 | B40: 1009574120 | C40: 21.08.2021 | D40: NA | E40: NO SIGNAL | F40: Def Tag Available | G40: 775244099237 | H40: IR | I40: JADE HD | J40: A042 | K40: =VLOOKUP(J40,Sheet2!A:B,2,0) -> ANKIT RANA | L40: 2 | M40: =VLOOKUP(L40,Sheet2!D:E,2,0) -> Tuner Section | N40: 6 | O40: =VLOOKUP(N40,Sheet2!G:H,2,0) -> No Signal | P40: 12 | Q40: =VLOOKUP(P40,Sheet2!J:K,2,0) -> IR Declared due to Others ( IR Normal)TB | R40: IR | S40: =VLOOKUP(R40,Sheet2!N:O,2,0) -> IREPARABLE | T40: =VLOOKUP(P40,Sheet2!Q:R,2,0) -> IR Normal - BER to IR | U40: IR CID - Tampered Track burn out | V40: 11 | W40: =VLOOKUP(V40,Sheet2!Q:R,2,0) -> IR Normal - Track burn out | X40: =J40 -> A042 | Y40: =VLOOKUP(X40,Sheet2!A:B,2,0) -> ANKIT RANA | Z40: U502 | AA40: 02.09.2021 | AB40: - | AC40: =LEFT(G40,2) -> 77 | AE40: HIMANSHU
...

Sheet Sheet2
E1: Object Part | H1: Fault Observed | K1: Fault Reason | O1: Action | Q1: CODE | R1: Reason for IR
A2: Main WorkCt | B2: T-NAME | C2: DETAILS | D2: CODE | E2: DESCRIPTION | F2: DETAILS | G2: CODE | H2: DESCRIPTION | I2: DETAILS | J2: CODE | K2: DESCRIPTION | M2: DETAILS | N2: CODE | O2: DESCRIPTION | Q2: 1 | R2: IR CID - Water log from IF port
A3: A002 | B3: VIJAY RANA | C3: Object Part | D3: 1 | E3: Power Supply Section | F3: Damage – Fault Codes | G3: 1 | H3: Dead | I3: Cause – Reason Codes | J3: 1 | K3: NFF | L3: NFF | M3: Task – Action Codes | N3: 1 | O3: NFF | Q3: 2 | R3: IR CID - Water log from other area | V3: DRY SOLDER
A4: A003 | B4: JAIMIN MAKWANA | C4: Object Part | D4: 2 | E4: Tuner Section | F4: Damage – Fault Codes | G4: 2 | H4: Dead Intermittent | I4: Cause – Reason Codes | J4: 2 | K4: NFF :- Software downloaded | L4: NFF | M4: Task – Action Codes | N4: 2 | O4: REPAIRED | Q4: 3 | R4: IR CID - Tampered TrackOpen/Reworkdone | V4: DRY SOLDER
A5: A004 | B5: JAYESH NAI | C5: Object Part | D5: 3 | E5: Video Section | F5: Damage – Fault Codes | G5: 3 | H5: Blue/Black /Blank Screen | I5: Cause – Reason Codes | J5: 3 | K5: NFF :- Master reset | L5: NFF | M5: Task – Action Codes | N5: BER | O5: BEYOND ECONOMIC REPAIR | Q5: 4 | R5: IR CID - Tampered Track burn out | V5: DRY SOLDER
A6: A005 | B6: VASANT PARMAR | C6: Object Part | D6: 4 | E6: Audio Section | F6: Damage – Fault Codes | G6: 4 | H6: All LED glow | I6: Cause – Reason Codes | J6: =+J5+1 -> 4 | K6: NFF :-Corrective Actions Taken | L6: NFF | M6: Task – Action Codes | N6: IR | O6: IREPARABLE | Q6: 5 | R6: IR CID - Water log fully due to Flood | V6: COMPONENTS
A7: A006 | B7: TAKHAT SOLANKI | C7: Object Part | D7: 5 | E7: Main Processor CPU BGA | F7: Damage – Fault Codes | G7: 5 | H7: LED Not glow STB functions are OK | I7: Cause – Reason Codes | J7: =+J6+1 -> 5 | K7: NFF:- IP Clean/G Service | L7: NFF:- IP Clean/G Service | N7: - | O7: - | Q7: 6 | R7: IR CID -Fullydamage-Broken/Dent/Burn out | V7: TRACK DAMAGE
A8: A007 | B8: HARIRAM GUPTA | C8: Object Part | D8: 6 | E8: Flash /EPROM/NVRAM | F8: Damage – Fault Codes | G8: 6 | H8: No Signal | I8: Cause – Reason Codes | J8: =+J7+1 -> 6 | K8: Component Replaced | L8: COMPONENTS | Q8: 7 | R8: IR CID -Tampered Backside ports&VCreader | V8: COMPONENTS
A9: A008 | B9: NILESH NAGAR | C9: Object Part | D9: 7 | E9: Card Reader Section | F9: Damage – Fault Codes | G9: 7 | H9: No Signal - Intermittent | I9: Cause – Reason Codes | J9: =+J8+1 -> 7 | K9: Component Missing Replaced | L9: COMPONENTS | Q9: 8 | R9: IR Normal -TrackRust/InternalDamage/open | V9: COMPONENTS
A10: A009 | B10: AKASH BAROT | C10: Object Part | D10: 8 | E10: Front Panel PCB Section | F10: Damage – Fault Codes | G10: 8 | H10: Signal Low | I10: Cause – Reason Codes | J10: =+J9+1 -> 8 | K10: BER -BGA Replaced | L10: COMPONENTS | Q10: 9 | R10: IR Normal - Multiple time repair | V10: COMPONENTS
A11: A010 | B11: BHUPENDRA DABHI | C11: Object Part | D11: 9 | E11: HDD | F11: Damage – Fault Codes | G11: 9 | H11: No Audio - AV | I11: Cause – Reason Codes | J11: =+J10+1 -> 9 | K11: Dry Solder Rectified | L11: DRY SOLDER | Q11: 10 | R11: IR Normal - Multiple components failure | V11: DRY SOLDER
A12: A011 | B12: PRADIP YADAV | C12: Object Part | D12: 10 | E12: Fan | F12: Damage – Fault Codes | G12: 10 | H12: No Audio - HDMI | I12: Cause – Reason Codes | J12: 10 | K12: BER -Dry Solder BGA Rectified | L12: DRY SOLDER | Q12: 11 | R12: IR Normal - Track burn out | V12: NFF
A13: A012 | B13: LUCKY PATIL | C13: Object Part | D13: 11 | E13: HDMI Section | F13: Damage – Fault Codes | G13: 11 | H13: No Audio - RF | I13: Cause – Reason Codes | J13: =+J12+1 -> 11 | K13: IR Declared due to CID -TA | L13: - | Q13: 12 | R13: IR Normal - BER to IR | V13: NFF
A14: A013 | B14: VIVEK SHAH | C14: Object Part | D14: 12 | E14: Ethernet / USB | F14: Damage – Fault Codes | G14: 12 | H14: No Audio - SPDIF | I14: Cause – Reason Codes | J14: =+J13+1 -> 12 | K14: IR Declared due to Others ( IR Normal)TB | L14: - | Q14: 13 | R14: IR Normal -BGA/MICO ULC VC chip failure
A15: A014 | B15: HARSHAD CHUHAN | C15: Object Part | D15: 13 | E15: Software | F15: Damage – Fault Codes | G15: 13 | H15: No Audio - Optical Out put | I15: Cause – Reason Codes | J15: =+J14+1 -> 13 | K15: IR CID but repaired OK | L15: COMPONENTS
A16: A015 | B16: PARIXIT PANDYA | C16: Object Part | D16: 14 | E16: Cosmetic | F16: Damage – Fault Codes | G16: 14 | H16: No Audio Intermittent | I16: Cause – Reason Codes | J16: =+J15+1 -> 14 | K16: IR Others but repaired OK | L16: COMPONENTS
A17: A018 | B17: PRAKASH CHAVDA | D17: - | E17: - | F17: Damage – Fault Codes | G17: 15 | H17: No Video - AV | I17: Cause – Reason Codes | J17: =+J16+1 -> 15 | K17: Modiffed/Corrected/Re fixed OK | L17: NFF
A18: A031 | B18: NITIN PRANAMI | F18: Damage – Fault Codes | G18: 16 | H18: No Video - HDMI | I18: Cause – Reason Codes | J18: =+J17+1 -> 16 | K18: Parts Pending | L18: - | O18: Status | P18: Tag Details | Q18: MATERIAL CODE
A19: A037 | B19: JAGDISH KOSHTI | F19: Damage – Fault Codes | G19: 17 | H19: No Video - Component | I19: Cause – Reason Codes | J19: =+J18+1 -> 17 | K19: BGA Replacement Pending | L19: - | O19: BER REPAIRED | P19: Def Tag Available | Q19: STD
A20: A040 | B20: PRASHANT SONVANE | F20: Damage – Fault Codes | G20: 18 | H20: No Video- RF | I20: Cause – Reason Codes | J20: =+J19+1 -> 18 | K20: STB OK Cosmetic Pending | L20: - | O20: REPAIRED | P20: DOA Tag Available | Q20: KAON HD
A21: A041 | B21: PRASHANT,AKASH | F21: Damage – Fault Codes | G21: 19 | H21: No Video - Intermittent | I21: Cause – Reason Codes | J21: =+J20+1 -> 19 | K21: STB OK Pending Others | L21: - | O21: NFF | P21: NA(Tag Not Available) | Q21: SAMSUNG HD
A22: A042 | B22: ANKIT RANA | F22: Damage – Fault Codes | G22: 20 | H22: No Audio /Video -AV | I22: Cause – Reason Codes | J22: 20 | K22: WIP | L22: - | O22: SOAKING FAIL REPAIRED | P22: Tag Availble but only SR area details available | Q22: TECH HD
A23: A050 | B23: PIYUSH CHAVDA | F23: Damage – Fault Codes | G23: 21 | H23: No Audio /Video - HDMI | I23: Cause – Reason Codes | J23: =+J22+1 -> 21 | K23: Awaiting Repair | L23: - | O23: QC FAIL REPAIRED | P23: Upgrade Tag Available | Q23: PVR SD
A24: A051 | B24: AJAY KOSHTI | F24: Damage – Fault Codes | G24: 22 | H24: No Audio /Video - RF | I24: Cause – Reason Codes | J24: =+J23+1 -> 22 | K24: Cosmetic-Top cover | L24: - | O24: IMPEDENCE FAIL REPAIRED | P24: NFF tag available | Q24: PVR HD
A25: A053 | B25: DEVENDRA RAJPUT | F25: Damage – Fault Codes | G25: 23 | H25: NO Audio/Video -Intermittent | I25: Cause – Reason Codes | J25: =+J24+1 -> 23 | K25: Cosmetic-Front Panel | L25: - | O25: IR REPAIRED | P25: IMPEDENCE FAIL | Q25: JADE HD
A26: A056 | B26: ISHWAR | F26: Damage – Fault Codes | G26: 24 | H26: STB Auto moving -Stand by mode | I26: Cause – Reason Codes | J26: =+J25+1 -> 24 | K26: Cosmetic -Front Panel Door | L26: - | O26: COLD SOAK FAIL REPAIRED | Q26: NOVA HD
A27: A061 | B27: GAJENDRA GARASIYA | F27: Damage – Fault Codes | G27: 25 | H27: STB Not Responding form RCU | I27: Cause – Reason Codes | J27: =+J26+1 -> 25 | K27: Cosmetic -Bottom panel | L27: - | Q27: T-51
A28: A063 | B28: SHANI GOHIL | F28: Damage – Fault Codes | G28: 26 | H28: STB Moving to Standby while using Remote | J28: 26 | K28: Component Replaced & DrySolder rectified | Q28: HEERA
A29: A065 | B29: NIKHIL KAMADE | F29: Damage – Fault Codes | G29: 27 | H29: STB Rebooting Continuously | J29: 27 | K29: Technical support pending from Vendor | Q29: PANNA
A30: A068 | B30: GHANSHYAM VYAS | F30: Damage – Fault Codes | G30: 28 | H30: Hang and Freeze video - AV | J30: 28 | K30: Physical scrap pending | Q30: SKY WORTH
A31: A077 | B31: ARUN KORI | F31: Damage – Fault Codes | G31: 29 | H31: Hang and Freeze video - HDMI | J31: 28 | K31: Replacement pending from vendor | Q31: BINGE
A32: A079 | B32: ARPIT PARMAR | F32: Damage – Fault Codes | G32: 30 | H32: Hang and Freeze video - Component | J32: 28 | K32: Others
A33: A052 | B33: MAHESH RAWAL | F33: Damage – Fault Codes | G33: 31 | H33: Hang and Freeze video - RF
A34: A053 | B34: DEVENDRA RAJPUT | F34: Damage – Fault Codes | G34: 32 | H34: Hang & Freeze video-Recording Play back
A35: A054 | B35: RANJIT GOHEL | F35: Damage – Fault Codes | G35: 33 | H35: Software download failure
A36: A055 | B36: SAILESH CHAUHAN | F36: Damage – Fault Codes | G36: 34 | H36: Missing - T Sky Logo
A37: A056 | B37: VIJAY VAGHELA | F37: Damage – Fault Codes | G37: 35 | H37: Missing - Few Channels
A38: A057 | B38: MAYUR TRIVEDI | F38: Damage – Fault Codes | G38: 36 | H38: Error -1
A39: A058 | B39: SUNIL | F39: Damage – Fault Codes | G39: 37 | H39: Error -2
A40: A059 | B40: DINESH VAGHELA | F40: Damage – Fault Codes | G40: 38 | H40: Error- 14
...

Sheet Sheet3
